<?xml version="1.0" ?>
<!-- =================================================================================== -->
<!-- |    This document was autogenerated by xacro from armbot.urdf.xacro              | -->
<!-- |    EDITING THIS FILE BY HAND IS NOT RECOMMENDED                                 | -->
<!-- =================================================================================== -->
<robot name="armbot">
  <material name="blue">
    <color rgba="0 0 0.8 1"/>
  </material>
  <material name="black">
    <color rgba="0 0 0 1"/>
  </material>
  <material name="white">
    <color rgba="1 1 1 1"/>
  </material>
  <link name="base_link"/>
  <link name="chesis">
    <visual>
      <geometry>
        <box size="0.3 0.2 0.08"/>
      </geometry>
      <material name="blue"/>
    </visual>
    <collision>
      <geometry>
        <box size="0.3 0.2 0.08"/>
      </geometry>
    </collision>
    <inertial>
      <mass value="0.5"/>
      <inertia ixx="0.0019333333333333338" ixy="0.0" ixz="0.0" iyy="0.004016666666666667" iyz="0.0" izz="0.005416666666666667"/>
    </inertial>
  </link>
  <gazebo reference="chesis">
    <material>Gazebo/Blue</material>
  </gazebo>
  <joint name="fixed_joint" type="fixed">
    <parent link="base_link"/>
    <child link="chesis"/>
  </joint>
  <link name="front_left_wheel">
    <visual>
      <origin rpy="1.5707963267948966 0 0" xyz="0 0 0"/>
      <geometry>
        <cylinder length="0.04" radius="0.08"/>
      </geometry>
      <material name="black"/>
    </visual>
    <collision>
      <origin rpy="1.5707963267948966 0 0" xyz="0 0 0"/>
      <geometry>
        <cylinder length="0.04" radius="0.08"/>
      </geometry>
    </collision>
    <inertial>
      <mass value="0.1"/>
      <inertia ixx="0.00017333333333333334" ixy="0.0" ixz="0.0" iyy="0.00017333333333333334" iyz="0.0" izz="0.00032"/>
    </inertial>
  </link>
  <joint name="front_left_wheel_joint" type="continuous">
    <axis rpy="0 0 0" xyz="0 1 0"/>
    <parent link="chesis"/>
    <child link="front_left_wheel"/>
    <origin rpy="0 0 0" xyz="0.09 0.13200000000000003 0"/>
    <dynamics damping="0"/>
  </joint>
  <gazebo reference="front_left_wheel">
    <material>Gazebo/DarkGray</material>
  </gazebo>
  <transmission name="front_left_wheel_trans">
    <type>transmission_interface/SimpleTransmission</type>
    <actuator name="front_left_wheel_motor">
      <mechanicalReduction>1</mechanicalReduction>
    </actuator>
    <joint name="front_left_wheel_joint">
      <hardwareInterface>hardware_interface/VelocityJointInterface</hardwareInterface>
    </joint>
  </transmission>
  <link name="front_right_wheel">
    <visual>
      <origin rpy="1.5707963267948966 0 0" xyz="0 0 0"/>
      <geometry>
        <cylinder length="0.04" radius="0.08"/>
      </geometry>
      <material name="black"/>
    </visual>
    <collision>
      <origin rpy="1.5707963267948966 0 0" xyz="0 0 0"/>
      <geometry>
        <cylinder length="0.04" radius="0.08"/>
      </geometry>
    </collision>
    <inertial>
      <mass value="0.1"/>
      <inertia ixx="0.00017333333333333334" ixy="0.0" ixz="0.0" iyy="0.00017333333333333334" iyz="0.0" izz="0.00032"/>
    </inertial>
  </link>
  <joint name="front_right_wheel_joint" type="continuous">
    <axis rpy="0 0 0" xyz="0 1 0"/>
    <parent link="chesis"/>
    <child link="front_right_wheel"/>
    <origin rpy="0 0 0" xyz="0.09 -0.13200000000000003 0"/>
    <dynamics damping="0"/>
  </joint>
  <gazebo reference="front_right_wheel">
    <material>Gazebo/DarkGray</material>
  </gazebo>
  <transmission name="front_right_wheel_trans">
    <type>transmission_interface/SimpleTransmission</type>
    <actuator name="front_right_wheel_motor">
      <mechanicalReduction>1</mechanicalReduction>
    </actuator>
    <joint name="front_right_wheel_joint">
      <hardwareInterface>hardware_interface/VelocityJointInterface</hardwareInterface>
    </joint>
  </transmission>
  <link name="back_left_wheel">
    <visual>
      <origin rpy="1.5707963267948966 0 0" xyz="0 0 0"/>
      <geometry>
        <cylinder length="0.04" radius="0.08"/>
      </geometry>
      <material name="black"/>
    </visual>
    <collision>
      <origin rpy="1.5707963267948966 0 0" xyz="0 0 0"/>
      <geometry>
        <cylinder length="0.04" radius="0.08"/>
      </geometry>
    </collision>
    <inertial>
      <mass value="0.1"/>
      <inertia ixx="0.00017333333333333334" ixy="0.0" ixz="0.0" iyy="0.00017333333333333334" iyz="0.0" izz="0.00032"/>
    </inertial>
  </link>
  <joint name="back_left_wheel_joint" type="continuous">
    <axis rpy="0 0 0" xyz="0 1 0"/>
    <parent link="chesis"/>
    <child link="back_left_wheel"/>
    <origin rpy="0 0 0" xyz="-0.09 0.13200000000000003 0"/>
    <dynamics damping="0"/>
  </joint>
  <gazebo reference="back_left_wheel">
    <material>Gazebo/DarkGray</material>
  </gazebo>
  <transmission name="back_left_wheel_trans">
    <type>transmission_interface/SimpleTransmission</type>
    <actuator name="back_left_wheel_motor">
      <mechanicalReduction>1</mechanicalReduction>
    </actuator>
    <joint name="back_left_wheel_joint">
      <hardwareInterface>hardware_interface/VelocityJointInterface</hardwareInterface>
    </joint>
  </transmission>
  <link name="back_right_wheel">
    <visual>
      <origin rpy="1.5707963267948966 0 0" xyz="0 0 0"/>
      <geometry>
        <cylinder length="0.04" radius="0.08"/>
      </geometry>
      <material name="black"/>
    </visual>
    <collision>
      <origin rpy="1.5707963267948966 0 0" xyz="0 0 0"/>
      <geometry>
        <cylinder length="0.04" radius="0.08"/>
      </geometry>
    </collision>
    <inertial>
      <mass value="0.1"/>
      <inertia ixx="0.00017333333333333334" ixy="0.0" ixz="0.0" iyy="0.00017333333333333334" iyz="0.0" izz="0.00032"/>
    </inertial>
  </link>
  <joint name="back_right_wheel_joint" type="continuous">
    <axis rpy="0 0 0" xyz="0 1 0"/>
    <parent link="chesis"/>
    <child link="back_right_wheel"/>
    <origin rpy="0 0 0" xyz="-0.09 -0.13200000000000003 0"/>
    <dynamics damping="0"/>
  </joint>
  <gazebo reference="back_right_wheel">
    <material>Gazebo/DarkGray</material>
  </gazebo>
  <transmission name="back_right_wheel_trans">
    <type>transmission_interface/SimpleTransmission</type>
    <actuator name="back_right_wheel_motor">
      <mechanicalReduction>1</mechanicalReduction>
    </actuator>
    <joint name="back_right_wheel_joint">
      <hardwareInterface>hardware_interface/VelocityJointInterface</hardwareInterface>
    </joint>
  </transmission>
  <link name="armbot_rgb_camera">
    <collision>
      <origin rpy="0 0 0" xyz="0 0 0"/>
      <geometry>
        <box size="0.001 0.008 0.008"/>
      </geometry>
    </collision>
    <visual>
      <origin rpy="0 0 0" xyz="0 0 0"/>
      <geometry>
        <box size="0.001 0.008 0.008"/>
      </geometry>
    </visual>
    <!-- <inertial>
        <mass value="0.01" />
        <origin xyz="0 0 0" rpy="0 0 0"/>
        <inertia ixx="5.3e-8" ixy="0" ixz="0" iyy="6.7e-9" iyz="0" izz="6.7e-9" />
      </inertial> -->
  </link>
  <joint name="armbot_rgb_camera_joint" type="fixed">
    <axis xyz="1 0 0"/>
    <origin rpy="0 0 0" xyz="0.15014999999999998 0 0.02"/>
    <parent link="chesis"/>
    <child link="armbot_rgb_camera"/>
  </joint>
  <gazebo reference="armbot_rgb_camera">
    <sensor name="armbot_rgb_camera" type="camera">
      <update_rate>30.0</update_rate>
      <camera name="armbot_rgb_camera">
        <horizontal_fov>1.3962634</horizontal_fov>
        <image>
          <width>800</width>
          <height>800</height>
          <format>R8G8B8</format>
        </image>
        <clip>
          <near>0.02</near>
          <far>300</far>
        </clip>
        <noise>
          <type>gaussian</type>
          <mean>0.0</mean>
          <stddev>0.007</stddev>
        </noise>
      </camera>
      <plugin filename="libgazebo_ros_camera.so" name="camera_controller">
        <alwaysOn>true</alwaysOn>
        <updateRate>0.0</updateRate>
        <cameraName>armbot_rgb_camera</cameraName>
        <imageTopicName>image_raw</imageTopicName>
        <cameraInfoTopicName>camera_info</cameraInfoTopicName>
        <frameName>armbot_rgb_camera</frameName>
        <hackBaseline>0.07</hackBaseline>
        <distortionK1>0.0</distortionK1>
        <distortionK2>0.0</distortionK2>
        <distortionK3>0.0</distortionK3>
        <distortionT1>0.0</distortionT1>
        <distortionT2>0.0</distortionT2>
      </plugin>
    </sensor>
    <material>Gazebo/Gray</material>
  </gazebo>
  <link name="armbot_depth_camera">
    <collision>
      <origin rpy="0 0 0" xyz="0 0 0"/>
      <geometry>
        <box size="0.001 0.08 0.01"/>
      </geometry>
    </collision>
    <visual>
      <origin rpy="0 0 0" xyz="0 0 0"/>
      <geometry>
        <box size="0.001 0.08 0.01"/>
      </geometry>
    </visual>
    <!-- <inertial>
        <mass value="0.05" />
        <origin xyz="0 0 0" rpy="0 0 0"/>
        <inertia ixx="2.7e-5" ixy="0" ixz="0" iyy="4.2e-7" iyz="0" izz="2.67e-5" />
      </inertial> -->
  </link>
  <joint name="armbot_depth_camera_joint" type="fixed">
    <axis xyz="1 0 0"/>
    <origin rpy="0 0 0" xyz="0.15014999999999998 0 0"/>
    <parent link="chesis"/>
    <child link="armbot_depth_camera"/>
  </joint>
  <link name="camera_depth_link"/>
  <joint name="cameraLeft_depth_joint" type="fixed">
    <origin rpy="-1.5707963267948966 0 -1.5707963267948966 " xyz="0 0 0"/>
    <parent link="armbot_depth_camera"/>
    <child link="camera_depth_link"/>
  </joint>
  <!-- Additional transformation link needed due to frame convention mismatch between gazebo and kinect in rviz
    https://answers.ros.org/question/218395/libgazebo_ros_openni_kinectso-depth-pointcloud-wrong-tf/ -->
  <gazebo reference="armbot_depth_camera">
    <sensor name="armbot_depth_camera_camera" type="depth">
      <update_rate>20</update_rate>
      <camera>
        <horizontal_fov>1.047198</horizontal_fov>
        <image>
          <width>640</width>
          <height>480</height>
          <format>R8G8B8</format>
        </image>
        <clip>
          <near>0.001</near>
          <far>3</far>
        </clip>
      </camera>
      <plugin filename="libgazebo_ros_openni_kinect.so" name="armbot_depth_camera_controller">
        <baseline>0.2</baseline>
        <alwaysOn>true</alwaysOn>
        <updateRate>1.0</updateRate>
        <cameraName>armbot_depth_camera_ir</cameraName>
        <imageTopicName>/armbot_depth_camera/depth/image_raw</imageTopicName>
        <cameraInfoTopicName>/armbot_depth_camera/depth/camera_info</cameraInfoTopicName>
        <depthImageTopicName>/armbot_depth_camera/depth/image_raw</depthImageTopicName>
        <depthImageInfoTopicName>/armbot_depth_camera/depth/camera_info</depthImageInfoTopicName>
        <pointCloudTopicName>/armbot_depth_camera/depth/points</pointCloudTopicName>
        <frameName>camera_depth_link</frameName>
        <pointCloudCutoff>0.001</pointCloudCutoff>
        <pointCloudCutoffMax>3.0</pointCloudCutoffMax>
        <distortionK1>0.00000001</distortionK1>
        <distortionK2>0.00000001</distortionK2>
        <distortionK3>0.00000001</distortionK3>
        <distortionT1>0.00000001</distortionT1>
        <distortionT2>0.00000001</distortionT2>
        <CxPrime>0</CxPrime>
        <Cx>0</Cx>
        <Cy>0</Cy>
        <focalLength>0</focalLength>
        <hackBaseline>0</hackBaseline>
      </plugin>
    </sensor>
  </gazebo>
  <material name="White">
    <color rgba="0.87 0.90 0.87 1.0"/>
  </material>
  <material name="Black">
    <color rgba="0.08 0.08 0.08 1.0"/>
  </material>
  <material name="Gray">
    <color rgba="0.2 0.2 0.21 1.0"/>
  </material>
  <material name="Green">
    <color rgba="0.22 0.32 0.14 1.0"/>
  </material>
  <transmission name="arm_shoulder_pan_trans">
    <type>transmission_interface/SimpleTransmission</type>
    <actuator name="arm_shoulder_pan_motor">
      <mechanicalReduction>1</mechanicalReduction>
    </actuator>
    <joint name="arm_shoulder_pan_joint">
      <hardwareInterface>hardware_interface/PositionJointInterface</hardwareInterface>
    </joint>
  </transmission>
  <transmission name="arm_shoulder_lift_trans">
    <type>transmission_interface/SimpleTransmission</type>
    <actuator name="arm_shoulder_lift_motor">
      <mechanicalReduction>1</mechanicalReduction>
    </actuator>
    <joint name="arm_shoulder_lift_joint">
      <hardwareInterface>hardware_interface/PositionJointInterface</hardwareInterface>
    </joint>
  </transmission>
  <transmission name="arm_elbow_flex_trans">
    <type>transmission_interface/SimpleTransmission</type>
    <actuator name="arm_elbow_flex_motor">
      <mechanicalReduction>1</mechanicalReduction>
    </actuator>
    <joint name="arm_elbow_flex_joint">
      <hardwareInterface>hardware_interface/PositionJointInterface</hardwareInterface>
    </joint>
  </transmission>
  <transmission name="arm_wrist_flex_trans">
    <type>transmission_interface/SimpleTransmission</type>
    <actuator name="arm_wrist_flex_motor">
      <mechanicalReduction>1</mechanicalReduction>
    </actuator>
    <joint name="arm_wrist_flex_joint">
      <hardwareInterface>hardware_interface/PositionJointInterface</hardwareInterface>
    </joint>
  </transmission>
  <transmission name="gripper_trans">
    <type>transmission_interface/SimpleTransmission</type>
    <actuator name="gripper_motor">
      <mechanicalReduction>1</mechanicalReduction>
    </actuator>
    <joint name="gripper_joint">
      <hardwareInterface>hardware_interface/PositionJointInterface</hardwareInterface>
    </joint>
  </transmission>
  <link name="shoulder_imu">
    <!--       <collision>
        <origin xyz="0 0 0" rpy="0 0 0"/>
        <geometry>
          <xacro:insert_block name="box"/>
        </geometry>
      </collision> -->
    <visual>
      <origin rpy="0 0 0" xyz="0 0 0"/>
      <geometry>
        <box size="0.008 0.008 0.001"/>
      </geometry>
    </visual>
    <!--       <inertial>
        <mass value="0.01" />
        <origin xyz="0 0 0" rpy="0 0 0"/>
        <inertia ixx="5.3e-8" ixy="0" ixz="0" iyy="6.7e-9" iyz="0" izz="6.7e-9" />
      </inertial> -->
  </link>
  <joint name="shoulder_imu_joint" type="fixed">
    <axis xyz="0 0 1"/>
    <origin rpy="0 0 0" xyz="0 0 0"/>
    <parent link="arm_shoulder_lift_link"/>
    <child link="shoulder_imu"/>
  </joint>
  <gazebo reference="shoulder_imu">
    <gravity>true</gravity>
    <sensor name="shoulder_imu" type="imu">
      <always_on>true</always_on>
      <update_rate>100</update_rate>
      <visualize>true</visualize>
      <topic>__default_topic__</topic>
      <plugin filename="libgazebo_ros_imu_sensor.so" name="imu_plugin">
        <topicName>armbot/shoulder_imu</topicName>
        <bodyName>shoulder_imu_link</bodyName>
        <updateRateHZ>30.0</updateRateHZ>
        <gaussianNoise>0.0</gaussianNoise>
        <xyzOffset>0 0 0</xyzOffset>
        <rpyOffset>0 0 0</rpyOffset>
        <frameName>shoulder_imu</frameName>
      </plugin>
      <pose>0 0 0 0 0 0</pose>
    </sensor>
  </gazebo>
  <link name="elbow_imu">
    <!--       <collision>
        <origin xyz="0 0 0" rpy="0 0 0"/>
        <geometry>
          <xacro:insert_block name="box"/>
        </geometry>
      </collision> -->
    <visual>
      <origin rpy="0 0 0" xyz="0 0 0"/>
      <geometry>
        <box size="0.008 0.008 0.001"/>
      </geometry>
    </visual>
    <!--       <inertial>
        <mass value="0.01" />
        <origin xyz="0 0 0" rpy="0 0 0"/>
        <inertia ixx="5.3e-8" ixy="0" ixz="0" iyy="6.7e-9" iyz="0" izz="6.7e-9" />
      </inertial> -->
  </link>
  <joint name="elbow_imu_joint" type="fixed">
    <axis xyz="0 0 1"/>
    <origin rpy="0 0 0" xyz="0 0 0"/>
    <parent link="arm_elbow_flex_link"/>
    <child link="elbow_imu"/>
  </joint>
  <gazebo reference="elbow_imu">
    <gravity>true</gravity>
    <sensor name="elbow_imu" type="imu">
      <always_on>true</always_on>
      <update_rate>100</update_rate>
      <visualize>true</visualize>
      <topic>__default_topic__</topic>
      <plugin filename="libgazebo_ros_imu_sensor.so" name="imu_plugin">
        <topicName>armbot/elbow_imu</topicName>
        <bodyName>elbow_imu_link</bodyName>
        <updateRateHZ>30.0</updateRateHZ>
        <gaussianNoise>0.0</gaussianNoise>
        <xyzOffset>0 0 0</xyzOffset>
        <rpyOffset>0 0 0</rpyOffset>
        <frameName>elbow_imu</frameName>
      </plugin>
      <pose>0 0 0 0 0 0</pose>
    </sensor>
  </gazebo>
  <link name="wrist_imu">
    <!--       <collision>
        <origin xyz="0 0 0" rpy="0 0 0"/>
        <geometry>
          <xacro:insert_block name="box"/>
        </geometry>
      </collision> -->
    <visual>
      <origin rpy="0 0 0" xyz="0 0 0"/>
      <geometry>
        <box size="0.008 0.008 0.001"/>
      </geometry>
    </visual>
    <!--       <inertial>
        <mass value="0.01" />
        <origin xyz="0 0 0" rpy="0 0 0"/>
        <inertia ixx="5.3e-8" ixy="0" ixz="0" iyy="6.7e-9" iyz="0" izz="6.7e-9" />
      </inertial> -->
  </link>
  <joint name="wrist_imu_joint" type="fixed">
    <axis xyz="0 0 1"/>
    <origin rpy="0 0 0" xyz="0 0 0"/>
    <parent link="arm_wrist_flex_link"/>
    <child link="wrist_imu"/>
  </joint>
  <gazebo reference="wrist_imu">
    <gravity>true</gravity>
    <sensor name="wrist_imu" type="imu">
      <always_on>true</always_on>
      <update_rate>100</update_rate>
      <visualize>true</visualize>
      <topic>__default_topic__</topic>
      <plugin filename="libgazebo_ros_imu_sensor.so" name="imu_plugin">
        <topicName>armbot/wrist_imu</topicName>
        <bodyName>wrist_imu_link</bodyName>
        <updateRateHZ>30.0</updateRateHZ>
        <gaussianNoise>0.0</gaussianNoise>
        <xyzOffset>0 0 0</xyzOffset>
        <rpyOffset>0 0 0</rpyOffset>
        <frameName>wrist_imu</frameName>
      </plugin>
      <pose>0 0 0 0 0 0</pose>
    </sensor>
  </gazebo>
  <link name="arm_base_link"/>
  <joint name="arm_base_joint" type="fixed">
    <origin xyz="0.1 0 0.06"/>
    <parent link="chesis"/>
    <child link="arm_base_link"/>
  </joint>
  <joint name="arm_shoulder_pan_servo_joint" type="fixed">
    <origin rpy="1.570795 0 1.570795" xyz="0 0 0"/>
    <parent link="arm_base_link"/>
    <child link="arm_shoulder_pan_servo_link"/>
  </joint>
  <link name="arm_shoulder_pan_servo_link">
    <inertial>
      <mass value="0.055"/>
      <origin xyz="0 0 0"/>
      <inertia ixx="0.000017012" ixy="0.0" ixz="0.0" iyy="0.000013258" iyz="0.0" izz="0.000009483"/>
    </inertial>
    <visual>
      <origin rpy="0 0 0" xyz=" 0 0 0 "/>
      <geometry>
        <mesh filename="package://roboarm/meshes/turtlebot_arm/ax12_box.stl" scale="0.001 0.001 0.001"/>
      </geometry>
      <material name="Black"/>
    </visual>
    <collision>
      <origin rpy="0 0 0" xyz="0.0 0.0 -0.01241"/>
      <geometry>
        <box size="0.025 0.038 0.04762"/>
      </geometry>
    </collision>
  </link>
  <gazebo reference="arm_shoulder_pan_servo_link">
    <material>Gazebo/Black</material>
    <selfCollide>true</selfCollide>
    <gravity>true</gravity>
  </gazebo>
  <joint name="arm_shoulder_pan_joint" type="revolute">
    <origin rpy="-1.570795 1.570795 3.14159" xyz="0 0.019 0"/>
    <axis xyz="0 0 -1"/>
    <limit effort="1" lower="-2.617" upper="2.617" velocity="0.571"/>
    <dynamics friction="0.13"/>
    <parent link="arm_shoulder_pan_servo_link"/>
    <child link="arm_shoulder_pan_link"/>
  </joint>
  <link name="arm_shoulder_pan_link">
    <inertial>
      <mass value="0.008"/>
      <origin xyz="0 0 0"/>
      <inertia ixx="4.7066666666666675e-07" ixy="0" ixz="0" iyy="1.3793333333333333e-06" iyz="0" izz="1.0166666666666665e-06"/>
    </inertial>
    <visual>
      <origin rpy="0 0 0" xyz=" 0 0 0 "/>
      <geometry>
        <mesh filename="package://roboarm/meshes/turtlebot_arm/F3.stl" scale="0.001 0.001 0.001"/>
      </geometry>
      <material name="White"/>
    </visual>
    <collision>
      <origin rpy="0 0 0" xyz="0.0 0.0 -0.0045"/>
      <geometry>
        <box size="0.025 0.038 0.009"/>
      </geometry>
    </collision>
  </link>
  <gazebo reference="arm_shoulder_pan_link">
    <material>Gazebo/White</material>
    <selfCollide>true</selfCollide>
    <gravity>true</gravity>
  </gazebo>
  <joint name="arm_shoulder_lift_servo_joint" type="fixed">
    <origin rpy="0 3.14159 0" xyz="0 0 -0.041499999999999995"/>
    <parent link="arm_shoulder_pan_link"/>
    <child link="arm_shoulder_lift_servo_link"/>
  </joint>
  <link name="arm_shoulder_lift_servo_link">
    <inertial>
      <mass value="0.055"/>
      <origin xyz="0 0 0"/>
      <inertia ixx="0.000017012" ixy="0.0" ixz="0.0" iyy="0.000013258" iyz="0.0" izz="0.000009483"/>
    </inertial>
    <visual>
      <origin rpy="0 0 0" xyz=" 0 0 0 "/>
      <geometry>
        <mesh filename="package://roboarm/meshes/turtlebot_arm/ax12_box.stl" scale="0.001 0.001 0.001"/>
      </geometry>
      <material name="Black"/>
    </visual>
    <collision>
      <origin rpy="0 0 0" xyz="0.0 0.0 -0.01241"/>
      <geometry>
        <box size="0.025 0.038 0.04762"/>
      </geometry>
    </collision>
  </link>
  <gazebo reference="arm_shoulder_lift_servo_link">
    <material>Gazebo/Black</material>
    <selfCollide>true</selfCollide>
    <gravity>true</gravity>
  </gazebo>
  <joint name="arm_shoulder_lift_joint" type="revolute">
    <origin rpy="0 0 0" xyz="0 0 0"/>
    <axis xyz="0 1 0"/>
    <limit effort="1" lower="-2.617" upper="2.617" velocity="0.571"/>
    <dynamics friction="0.13"/>
    <parent link="arm_shoulder_lift_servo_link"/>
    <child link="arm_shoulder_lift_link"/>
  </joint>
  <link name="arm_shoulder_lift_link">
    <inertial>
      <mass value="0.016"/>
      <origin xyz="0 0 0"/>
      <inertia ixx="6.678666666666667e-06" ixy="0" ixz="0" iyy="4.181666666666667e-06" iyz="0" izz="8.769666666666667e-06"/>
    </inertial>
    <visual>
      <origin rpy="0 0 0" xyz=" 0 0 0 "/>
      <geometry>
        <mesh filename="package://roboarm/meshes/turtlebot_arm/F4.stl" scale="0.001 0.001 0.001"/>
      </geometry>
      <material name="White"/>
    </visual>
    <collision>
      <origin rpy="0 0 0" xyz="0.0 0.0 0.0215"/>
      <geometry>
        <box size="0.028 0.0485 0.065"/>
      </geometry>
    </collision>
  </link>
  <gazebo reference="arm_shoulder_lift_link">
    <material>Gazebo/White</material>
    <selfCollide>true</selfCollide>
    <gravity>true</gravity>
  </gazebo>
  <joint name="arm_shoulder_F10_0_joint" type="fixed">
    <origin rpy="0 0 0" xyz="0 0 0.0545"/>
    <parent link="arm_shoulder_lift_link"/>
    <child link="arm_shoulder_F10_0_link"/>
  </joint>
  <link name="arm_shoulder_F10_0_link">
    <inertial>
      <mass value="0.004"/>
      <origin xyz="0 0 0"/>
      <inertia ixx="2.136666666666667e-07" ixy="0" ixz="0" iyy="6.896666666666666e-07" iyz="0" izz="4.866666666666666e-07"/>
    </inertial>
    <visual>
      <origin rpy="0 0 0" xyz=" 0 0 0 "/>
      <geometry>
        <mesh filename="package://roboarm/meshes/turtlebot_arm/F10.stl" scale="0.001 0.001 0.001"/>
      </geometry>
      <material name="White"/>
    </visual>
    <collision>
      <origin rpy="0 0 0" xyz="0.0 0.0 0.0"/>
      <geometry>
        <box size="0.025 0.038 0.004"/>
      </geometry>
    </collision>
  </link>
  <gazebo reference="arm_shoulder_F10_0_link">
    <material>Gazebo/White</material>
    <selfCollide>true</selfCollide>
    <gravity>true</gravity>
  </gazebo>
  <joint name="arm_shoulder_F10_1_joint" type="fixed">
    <origin rpy="0 0 0" xyz="0 0 0.004"/>
    <parent link="arm_shoulder_F10_0_link"/>
    <child link="arm_shoulder_F10_1_link"/>
  </joint>
  <link name="arm_shoulder_F10_1_link">
    <inertial>
      <mass value="0.004"/>
      <origin xyz="0 0 0"/>
      <inertia ixx="2.136666666666667e-07" ixy="0" ixz="0" iyy="6.896666666666666e-07" iyz="0" izz="4.866666666666666e-07"/>
    </inertial>
    <visual>
      <origin rpy="0 0 0" xyz=" 0 0 0 "/>
      <geometry>
        <mesh filename="package://roboarm/meshes/turtlebot_arm/F10.stl" scale="0.001 0.001 0.001"/>
      </geometry>
      <material name="White"/>
    </visual>
    <collision>
      <origin rpy="0 0 0" xyz="0.0 0.0 0.0"/>
      <geometry>
        <box size="0.025 0.038 0.004"/>
      </geometry>
    </collision>
  </link>
  <gazebo reference="arm_shoulder_F10_1_link">
    <material>Gazebo/White</material>
    <selfCollide>true</selfCollide>
    <gravity>true</gravity>
  </gazebo>
  <joint name="arm_shoulder_F10_2_joint" type="fixed">
    <origin rpy="0 0 0" xyz="0 0 0.004"/>
    <parent link="arm_shoulder_F10_1_link"/>
    <child link="arm_shoulder_F10_2_link"/>
  </joint>
  <link name="arm_shoulder_F10_2_link">
    <inertial>
      <mass value="0.004"/>
      <origin xyz="0 0 0"/>
      <inertia ixx="2.136666666666667e-07" ixy="0" ixz="0" iyy="6.896666666666666e-07" iyz="0" izz="4.866666666666666e-07"/>
    </inertial>
    <visual>
      <origin rpy="0 0 0" xyz=" 0 0 0 "/>
      <geometry>
        <mesh filename="package://roboarm/meshes/turtlebot_arm/F10.stl" scale="0.001 0.001 0.001"/>
      </geometry>
      <material name="White"/>
    </visual>
    <collision>
      <origin rpy="0 0 0" xyz="0.0 0.0 0.0"/>
      <geometry>
        <box size="0.025 0.038 0.004"/>
      </geometry>
    </collision>
  </link>
  <gazebo reference="arm_shoulder_F10_2_link">
    <material>Gazebo/White</material>
    <selfCollide>true</selfCollide>
    <gravity>true</gravity>
  </gazebo>
  <joint name="arm_shoulder_F3_0_joint" type="fixed">
    <origin rpy="0 3.14159 0" xyz="0 0 0.002"/>
    <parent link="arm_shoulder_F10_2_link"/>
    <child link="arm_shoulder_F3_0_link"/>
  </joint>
  <link name="arm_shoulder_F3_0_link">
    <inertial>
      <mass value="0.005"/>
      <origin xyz="0 0 0"/>
      <inertia ixx="2.9416666666666673e-07" ixy="0" ixz="0" iyy="8.620833333333335e-07" iyz="0" izz="6.354166666666667e-07"/>
    </inertial>
    <visual>
      <origin rpy="0 0 0" xyz=" 0 0 0 "/>
      <geometry>
        <mesh filename="package://roboarm/meshes/turtlebot_arm/F3.stl" scale="0.001 0.001 0.001"/>
      </geometry>
      <material name="White"/>
    </visual>
    <collision>
      <origin rpy="0 0 0" xyz="0.0 0.0 -0.0045"/>
      <geometry>
        <box size="0.025 0.038 0.009"/>
      </geometry>
    </collision>
  </link>
  <gazebo reference="arm_shoulder_F3_0_link">
    <material>Gazebo/White</material>
    <selfCollide>true</selfCollide>
    <gravity>true</gravity>
  </gazebo>
  <joint name="arm_elbow_flex_servo_joint" type="fixed">
    <origin rpy="0 3.14159 0" xyz="0 0 -0.041499999999999995"/>
    <parent link="arm_shoulder_F3_0_link"/>
    <child link="arm_elbow_flex_servo_link"/>
  </joint>
  <link name="arm_elbow_flex_servo_link">
    <inertial>
      <mass value="0.055"/>
      <origin xyz="0 0 0"/>
      <inertia ixx="0.000017012" ixy="0.0" ixz="0.0" iyy="0.000013258" iyz="0.0" izz="0.000009483"/>
    </inertial>
    <visual>
      <origin rpy="0 0 0" xyz=" 0 0 0 "/>
      <geometry>
        <mesh filename="package://roboarm/meshes/turtlebot_arm/ax12_box.stl" scale="0.001 0.001 0.001"/>
      </geometry>
      <material name="Black"/>
    </visual>
    <collision>
      <origin rpy="0 0 0" xyz="0.0 0.0 -0.01241"/>
      <geometry>
        <box size="0.025 0.038 0.04762"/>
      </geometry>
    </collision>
  </link>
  <gazebo reference="arm_elbow_flex_servo_link">
    <material>Gazebo/Black</material>
    <selfCollide>true</selfCollide>
    <gravity>true</gravity>
  </gazebo>
  <joint name="arm_elbow_flex_joint" type="revolute">
    <origin rpy="0 0 0" xyz="0 0 0"/>
    <axis xyz="0 1 0"/>
    <limit effort="1" lower="-2.617" upper="2.617" velocity="0.571"/>
    <dynamics friction="0.13"/>
    <parent link="arm_elbow_flex_servo_link"/>
    <child link="arm_elbow_flex_link"/>
  </joint>
  <link name="arm_elbow_flex_link">
    <inertial>
      <mass value="0.016"/>
      <origin xyz="0 0 0"/>
      <inertia ixx="6.678666666666667e-06" ixy="0" ixz="0" iyy="4.181666666666667e-06" iyz="0" izz="8.769666666666667e-06"/>
    </inertial>
    <visual>
      <origin rpy="0 0 0" xyz=" 0 0 0 "/>
      <geometry>
        <mesh filename="package://roboarm/meshes/turtlebot_arm/F4.stl" scale="0.001 0.001 0.001"/>
      </geometry>
      <material name="White"/>
    </visual>
    <collision>
      <origin rpy="0 0 0" xyz="0.0 0.0 0.0215"/>
      <geometry>
        <box size="0.028 0.0485 0.065"/>
      </geometry>
    </collision>
  </link>
  <gazebo reference="arm_elbow_flex_link">
    <material>Gazebo/White</material>
    <selfCollide>true</selfCollide>
    <gravity>true</gravity>
  </gazebo>
  <joint name="arm_elbow_F10_0_joint" type="fixed">
    <origin rpy="0 0 0" xyz="0 0 0.0545"/>
    <parent link="arm_elbow_flex_link"/>
    <child link="arm_elbow_F10_0_link"/>
  </joint>
  <link name="arm_elbow_F10_0_link">
    <inertial>
      <mass value="0.004"/>
      <origin xyz="0 0 0"/>
      <inertia ixx="2.136666666666667e-07" ixy="0" ixz="0" iyy="6.896666666666666e-07" iyz="0" izz="4.866666666666666e-07"/>
    </inertial>
    <visual>
      <origin rpy="0 0 0" xyz=" 0 0 0 "/>
      <geometry>
        <mesh filename="package://roboarm/meshes/turtlebot_arm/F10.stl" scale="0.001 0.001 0.001"/>
      </geometry>
      <material name="White"/>
    </visual>
    <collision>
      <origin rpy="0 0 0" xyz="0.0 0.0 0.0"/>
      <geometry>
        <box size="0.025 0.038 0.004"/>
      </geometry>
    </collision>
  </link>
  <gazebo reference="arm_elbow_F10_0_link">
    <material>Gazebo/White</material>
    <selfCollide>true</selfCollide>
    <gravity>true</gravity>
  </gazebo>
  <joint name="arm_elbow_F10_1_joint" type="fixed">
    <origin rpy="0 0 0" xyz="0 0 0.004"/>
    <parent link="arm_elbow_F10_0_link"/>
    <child link="arm_elbow_F10_1_link"/>
  </joint>
  <link name="arm_elbow_F10_1_link">
    <inertial>
      <mass value="0.004"/>
      <origin xyz="0 0 0"/>
      <inertia ixx="2.136666666666667e-07" ixy="0" ixz="0" iyy="6.896666666666666e-07" iyz="0" izz="4.866666666666666e-07"/>
    </inertial>
    <visual>
      <origin rpy="0 0 0" xyz=" 0 0 0 "/>
      <geometry>
        <mesh filename="package://roboarm/meshes/turtlebot_arm/F10.stl" scale="0.001 0.001 0.001"/>
      </geometry>
      <material name="White"/>
    </visual>
    <collision>
      <origin rpy="0 0 0" xyz="0.0 0.0 0.0"/>
      <geometry>
        <box size="0.025 0.038 0.004"/>
      </geometry>
    </collision>
  </link>
  <gazebo reference="arm_elbow_F10_1_link">
    <material>Gazebo/White</material>
    <selfCollide>true</selfCollide>
    <gravity>true</gravity>
  </gazebo>
  <joint name="arm_elbow_F10_2_joint" type="fixed">
    <origin rpy="0 0 0" xyz="0 0 0.004"/>
    <parent link="arm_elbow_F10_1_link"/>
    <child link="arm_elbow_F10_2_link"/>
  </joint>
  <link name="arm_elbow_F10_2_link">
    <inertial>
      <mass value="0.004"/>
      <origin xyz="0 0 0"/>
      <inertia ixx="2.136666666666667e-07" ixy="0" ixz="0" iyy="6.896666666666666e-07" iyz="0" izz="4.866666666666666e-07"/>
    </inertial>
    <visual>
      <origin rpy="0 0 0" xyz=" 0 0 0 "/>
      <geometry>
        <mesh filename="package://roboarm/meshes/turtlebot_arm/F10.stl" scale="0.001 0.001 0.001"/>
      </geometry>
      <material name="White"/>
    </visual>
    <collision>
      <origin rpy="0 0 0" xyz="0.0 0.0 0.0"/>
      <geometry>
        <box size="0.025 0.038 0.004"/>
      </geometry>
    </collision>
  </link>
  <gazebo reference="arm_elbow_F10_2_link">
    <material>Gazebo/White</material>
    <selfCollide>true</selfCollide>
    <gravity>true</gravity>
  </gazebo>
  <joint name="arm_elbow_F3_0_joint" type="fixed">
    <origin rpy="0 3.14159 0" xyz="0 0 0.002"/>
    <parent link="arm_elbow_F10_2_link"/>
    <child link="arm_elbow_F3_0_link"/>
  </joint>
  <link name="arm_elbow_F3_0_link">
    <inertial>
      <mass value="0.005"/>
      <origin xyz="0 0 0"/>
      <inertia ixx="2.9416666666666673e-07" ixy="0" ixz="0" iyy="8.620833333333335e-07" iyz="0" izz="6.354166666666667e-07"/>
    </inertial>
    <visual>
      <origin rpy="0 0 0" xyz=" 0 0 0 "/>
      <geometry>
        <mesh filename="package://roboarm/meshes/turtlebot_arm/F3.stl" scale="0.001 0.001 0.001"/>
      </geometry>
      <material name="White"/>
    </visual>
    <collision>
      <origin rpy="0 0 0" xyz="0.0 0.0 -0.0045"/>
      <geometry>
        <box size="0.025 0.038 0.009"/>
      </geometry>
    </collision>
  </link>
  <gazebo reference="arm_elbow_F3_0_link">
    <material>Gazebo/White</material>
    <selfCollide>true</selfCollide>
    <gravity>true</gravity>
  </gazebo>
  <joint name="arm_wrist_flex_servo_joint" type="fixed">
    <origin rpy="0 3.14159 0" xyz="0 0 -0.041499999999999995"/>
    <parent link="arm_elbow_F3_0_link"/>
    <child link="arm_wrist_flex_servo_link"/>
  </joint>
  <link name="arm_wrist_flex_servo_link">
    <inertial>
      <mass value="0.055"/>
      <origin xyz="0 0 0"/>
      <inertia ixx="0.000017012" ixy="0.0" ixz="0.0" iyy="0.000013258" iyz="0.0" izz="0.000009483"/>
    </inertial>
    <visual>
      <origin rpy="0 0 0" xyz=" 0 0 0 "/>
      <geometry>
        <mesh filename="package://roboarm/meshes/turtlebot_arm/ax12_box.stl" scale="0.001 0.001 0.001"/>
      </geometry>
      <material name="Black"/>
    </visual>
    <collision>
      <origin rpy="0 0 0" xyz="0.0 0.0 -0.01241"/>
      <geometry>
        <box size="0.025 0.038 0.04762"/>
      </geometry>
    </collision>
  </link>
  <gazebo reference="arm_wrist_flex_servo_link">
    <material>Gazebo/Black</material>
    <selfCollide>true</selfCollide>
    <gravity>true</gravity>
  </gazebo>
  <joint name="arm_wrist_flex_joint" type="revolute">
    <origin rpy="0 0 0" xyz="0 0 0"/>
    <axis xyz="0 1 0"/>
    <limit effort="1" lower="-1.745" upper="1.745" velocity="0.571"/>
    <dynamics friction="0.13"/>
    <parent link="arm_wrist_flex_servo_link"/>
    <child link="arm_wrist_flex_link"/>
  </joint>
  <link name="arm_wrist_flex_link">
    <inertial>
      <mass value="0.01"/>
      <origin xyz="0 0 0"/>
      <inertia ixx="1.6927083333333335e-06" ixy="0" ixz="0" iyy="2.4810416666666672e-06" iyz="0" izz="3.1320833333333338e-06"/>
    </inertial>
    <visual>
      <origin rpy="0 0 0" xyz=" 0 0 0 "/>
      <geometry>
        <mesh filename="package://roboarm/meshes/turtlebot_arm/F2.stl" scale="0.001 0.001 0.001"/>
      </geometry>
      <material name="White"/>
    </visual>
    <collision>
      <origin rpy="0 0 0" xyz="0.0 0.0 0.00775"/>
      <geometry>
        <box size="0.025 0.0485 0.0375"/>
      </geometry>
    </collision>
  </link>
  <gazebo reference="arm_wrist_flex_link">
    <material>Gazebo/White</material>
    <selfCollide>true</selfCollide>
    <gravity>true</gravity>
  </gazebo>
  <joint name="arm_wrist_F3_0_joint" type="fixed">
    <origin rpy="0 3.14159 -1.570795" xyz="0 0.016 0.0265"/>
    <parent link="arm_wrist_flex_link"/>
    <child link="arm_wrist_F3_0_link"/>
  </joint>
  <link name="arm_wrist_F3_0_link">
    <inertial>
      <mass value="0.005"/>
      <origin xyz="0 0 0"/>
      <inertia ixx="2.9416666666666673e-07" ixy="0" ixz="0" iyy="8.620833333333335e-07" iyz="0" izz="6.354166666666667e-07"/>
    </inertial>
    <visual>
      <origin rpy="0 0 0" xyz=" 0 0 0 "/>
      <geometry>
        <mesh filename="package://roboarm/meshes/turtlebot_arm/F3.stl" scale="0.001 0.001 0.001"/>
      </geometry>
      <material name="White"/>
    </visual>
    <collision>
      <origin rpy="0 0 0" xyz="0.0 0.0 -0.0045"/>
      <geometry>
        <box size="0.025 0.038 0.009"/>
      </geometry>
    </collision>
  </link>
  <gazebo reference="arm_wrist_F3_0_link">
    <material>Gazebo/White</material>
    <selfCollide>true</selfCollide>
    <gravity>true</gravity>
  </gazebo>
  <joint name="gripper_servo_joint" type="fixed">
    <origin rpy="3.14159 1.570795 0" xyz="-0.02275 0 -0.019"/>
    <parent link="arm_wrist_F3_0_link"/>
    <child link="gripper_servo_link"/>
  </joint>
  <link name="gripper_servo_link">
    <inertial>
      <mass value="0.055"/>
      <origin xyz="0 0 0"/>
      <inertia ixx="0.000017012" ixy="0.0" ixz="0.0" iyy="0.000013258" iyz="0.0" izz="0.000009483"/>
    </inertial>
    <visual>
      <origin rpy="0 0 0" xyz=" 0 0 0 "/>
      <geometry>
        <mesh filename="package://roboarm/meshes/turtlebot_arm/ax12_box.stl" scale="0.001 0.001 0.001"/>
      </geometry>
      <material name="Black"/>
    </visual>
    <collision>
      <origin rpy="0 0 0" xyz="0.0 0.0 -0.01241"/>
      <geometry>
        <box size="0.025 0.038 0.04762"/>
      </geometry>
    </collision>
  </link>
  <gazebo reference="gripper_servo_link">
    <material>Gazebo/Black</material>
    <selfCollide>true</selfCollide>
    <gravity>true</gravity>
  </gazebo>
  <!-- finger 1 -->
  <joint name="gripper_joint" type="revolute">
    <origin rpy="0 0 0" xyz="0 0 0"/>
    <axis xyz="0 1 0"/>
    <limit effort="1" lower="-0.40" upper="0.46" velocity="0.785"/>
    <parent link="gripper_servo_link"/>
    <child link="gripper_active_link"/>
  </joint>
  <link name="gripper_active_link">
    <inertial>
      <mass value="0.010"/>
      <origin xyz="0 0 0"/>
      <inertia ixx="3.13e-6" ixy="0.0" ixz="0.0" iyy="2.48e-6" iyz="0.0" izz="1.69e-6"/>
    </inertial>
    <visual>
      <origin rpy="0 0 0" xyz=" 0 0 0 "/>
      <geometry>
        <mesh filename="package://roboarm/meshes/turtlebot_arm/F2.stl" scale="0.001 0.001 0.001"/>
      </geometry>
      <material name="White"/>
    </visual>
    <collision>
      <origin rpy="0 0 0" xyz="0.0 0.0 0.00775"/>
      <geometry>
        <box size="0.025 0.0375 0.0485"/>
      </geometry>
    </collision>
  </link>
  <joint name="gripper_active_finger_joint" type="fixed">
    <origin rpy="0 0 0" xyz="0 0 0.0265"/>
    <parent link="gripper_active_link"/>
    <child link="gripper_active_finger_link"/>
  </joint>
  <link name="gripper_active_finger_link">
    <inertial>
      <mass value="0.015"/>
      <origin xyz="0 0 0"/>
      <inertia ixx="8.129225e-06" ixy="0" ixz="0" iyy="9.469562625e-06" iyz="0" izz="2.2715626250000003e-06"/>
    </inertial>
    <visual>
      <origin rpy="0 0 0" xyz=" 0 0 0 "/>
      <geometry>
        <mesh filename="package://roboarm/meshes/turtlebot_arm/turtlebot_finger.stl" scale="0.001 0.001 0.001"/>
      </geometry>
      <material name="Green"/>
    </visual>
    <collision>
      <origin rpy="0 0 0" xyz="0.02645 0.0 -0.00655"/>
      <geometry>
        <box size="0.0783 0.03801 0.0193"/>
      </geometry>
    </collision>
  </link>
  <gazebo reference="gripper_active_finger_link">
    <material>Gazebo/Green</material>
    <selfCollide>true</selfCollide>
    <gravity>true</gravity>
  </gazebo>
  <joint name="gripper_static_joint" type="fixed">
    <origin rpy="0 3.14159 0" xyz="0 0 -0.041499999999999995"/>
    <parent link="gripper_servo_link"/>
    <child link="gripper_static_link"/>
  </joint>
  <link name="gripper_static_link">
    <inertial>
      <mass value="0.005"/>
      <origin xyz="0 0 0"/>
      <inertia ixx="2.9416666666666673e-07" ixy="0" ixz="0" iyy="8.620833333333335e-07" iyz="0" izz="6.354166666666667e-07"/>
    </inertial>
    <visual>
      <origin rpy="0 0 0" xyz=" 0 0 0 "/>
      <geometry>
        <mesh filename="package://roboarm/meshes/turtlebot_arm/F3.stl" scale="0.001 0.001 0.001"/>
      </geometry>
      <material name="White"/>
    </visual>
    <collision>
      <origin rpy="0 0 0" xyz="0.0 0.0 -0.0045"/>
      <geometry>
        <box size="0.025 0.038 0.009"/>
      </geometry>
    </collision>
  </link>
  <gazebo reference="gripper_static_link">
    <material>Gazebo/White</material>
    <selfCollide>true</selfCollide>
    <gravity>true</gravity>
  </gazebo>
  <joint name="gripper_static_finger_joint" type="fixed">
    <origin rpy="0 0 3.14159" xyz="0 0 0"/>
    <parent link="gripper_static_link"/>
    <child link="gripper_static_finger_link"/>
  </joint>
  <link name="gripper_static_finger_link">
    <inertial>
      <mass value="0.015"/>
      <origin xyz="0 0 0"/>
      <inertia ixx="8.129225e-06" ixy="0" ixz="0" iyy="9.469562625e-06" iyz="0" izz="2.2715626250000003e-06"/>
    </inertial>
    <visual>
      <origin rpy="0 0 0" xyz=" 0 0 0 "/>
      <geometry>
        <mesh filename="package://roboarm/meshes/turtlebot_arm/turtlebot_finger.stl" scale="0.001 0.001 0.001"/>
      </geometry>
      <material name="Green"/>
    </visual>
    <collision>
      <origin rpy="0 0 0" xyz="0.02645 0.0 -0.00655"/>
      <geometry>
        <box size="0.0783 0.03801 0.0193"/>
      </geometry>
    </collision>
  </link>
  <gazebo reference="gripper_static_finger_link">
    <material>Gazebo/Green</material>
    <selfCollide>true</selfCollide>
    <gravity>true</gravity>
  </gazebo>
  <gazebo reference="gripper_static_finger_link">
    <mu1 value="100.0"/>
    <mu2 value="50.0"/>
    <kp value="10000000.0"/>
    <kd value="1.0"/>
  </gazebo>
  <gazebo reference="gripper_active_finger_link">
    <mu1 value="100.0"/>
    <mu2 value="50.0"/>
    <kp value="10000000.0"/>
    <kd value="1.0"/>
  </gazebo>
  <gazebo>
    <plugin filename="libgazebo_grasp_fix.so" name="gazebo_grasp_fix">
      <robotNamespace>/armbot</robotNamespace>
      <arm>
        <arm_name>armbot</arm_name>
        <gripper_link>gripper_active_link</gripper_link>
        <gripper_link>arm_wrist_flex_link</gripper_link>
        <palm_link>arm_wrist_flex_link</palm_link>
      </arm>
      <forces_angle_tolerance>100</forces_angle_tolerance>
      <update_rate>4</update_rate>
      <grip_count_threshold>4</grip_count_threshold>
      <max_grip_count>8</max_grip_count>
      <release_tolerance>0.005</release_tolerance>
      <disable_collisions_on_attach>false</disable_collisions_on_attach>
      <contact_topic>__default_topic__</contact_topic>
    </plugin>
  </gazebo>
  <!-- Gazebo plugin for ROS Control -->
  <gazebo>
    <plugin filename="libgazebo_ros_control.so" name="gazebo_ros_control">
      <robotNamespace>/armbot</robotNamespace>
      <legacyModeNS>true</legacyModeNS>
      <robotSimType>gazebo_ros_control/DefaultRobotHWSim</robotSimType>
    </plugin>
  </gazebo>
</robot>
